Workbook

Sheet Data Flags Legend
A1: High internal standard recovery, corresponding analyte in sample. Reviewed and not disqualifying | B1: IS1 | C1: Internal standard recovery was above the method acceptance limits of 150%. Target analytes were detected in the sample. Impact on results is not expected based on analyst review. See comments. | D1: Analyst and validator concurrence required to release data. If this is not met, reanalysis and/or repreparation is required.
A2: High internal standard recovery, no analyte in sample | B2: IS2 | C2: Internal standard recovery was above the method acceptance limits. No target analytes were detected in the sample. | D2: Analyst and validator concurrence required to release data. If this is not met, reanalysis and/or repreparation is required.
A3: Low internal standard recovery, corresponding analyte in sample. Reviewed and not disqualifying | B3: IS3 | C3: Internal standard recovery was below the method acceptance limit of 50%. Target analytes were detected in the sample. Impact on results is not expected based on analyst review. See comments. | D3: Analyst and validator concurrence required to release data. If this is not met, reanalysis and/or repreparation is required.
A4: Low internal standard recovery, no analyte in sample. | B4: IS4 | C4: Internal standard recovery was below the method acceptance limits. No target analytes were detected in the sample. | D4: Analyst and validator concurrence required to release data. If this is not met, reanalysis and/or repreparation is required.
A5: Internal standards outside limit, disqualifying. | B5: IS5 | C5: Internal standard recovery was outside of method limits of 50-150%, and upon review is expected to impact data quality. Data not useable. [Margie would rather we said things like 'data biased low', but my impression is you prefer a go/no-go for data, right?] | D5: Sample re-analysis required; If failure persists, re-prepare sample and re-analyze.
A6: Laboratory duplicate precision failure | B6: D | C6: RPD/RSD for duplicate analysis exceeded method acceptance. | D6: Sample re-analysis required; If failure persists, further troubleshooting is required to improve precision and all samples analyzed since previous passing duplicate must be re-analyzed.
A7: Laboratory Reagent Blank (LRB) failure | B7: B | C7: Result is >50% of MRL. | D7: Flag LRB failure and sample results within 10-fold of the LRB concentration as biased high.
A9: Continuing Calibration Check (CCC) failure | B9: V1 | C9: Continuing calibration check (CCC) recovery was outside the method acceptance limits (70-130%). | D9: Samples analyzed since previous passing CCC must be re-analyzed. If failure persists, re-calibration is required. Upon recalibration, all other QC must be re-analyzed as well.
A10: Quality Control Sample (QCS) failure | B10: V2 | C10: Quality control sample (QCS) recovery was outside of the method acceptance limits (70-130%). | D10: Re-analysis of QCS required; if failure persists, re-preparation of QCS is required and re-calibration may be necessary. Upon recalibration, all other QC must be re-analyzed as well. No sample results may be reported if QCS failure occurs in batch.
A11: Inter-Batch Consistency check (IBC) failure | B11: V3 | C11: The inter-batch consistency check (IBC) sample was outside of acceptance criteria (80-120%). This suggests a systematic bias for the analytical batch relative to prior sample batches. | D11: Compare peak areas of calibration standards to those of previous batches to determine if source of failure is the calibration curve or the IBC itself. For IBC failure, re-preparation and/or re-analysis of IBC is required. For calibration curve failure, re-preparation and/or re-analysis of calibration curve is required. Upon recalibration, all other QC must be re-analyzed as well. No sample results may be reported if IBC failure occurs in batch.
A12: High Laboratory Fortified Blank (LFB) recovery | B12: L1 | C12: LFB results >150% for LFB-Low or >130% for LFB-High. Affected sample results biased high. | D12: Re-analysis of LFB required; If failure persists, re-prepare LFB and re-analyze. Re-preparation of spiking solution (PDS/SDS) may also be necessary. Affected samples, i.e. all samples analyzed since previous passing LFB, must be flagged.
A13: Low Laboratory Fortified Blank (LFB) recovery | B13: L2 | C13: LFB results <50% for LFB-Low or <70% for LFB-High. Affected sample results biased low. | D13: Re-analysis of LFB required; If failure persists, re-prepare LFB and re-analyze. Re-preparation of spiking solution (PDS/SDS) may also be necessary. Affected samples, i.e. all samples analyzed since previous passing LFB, must be flagged.
A14: Laboratory Fortified Sample Matrix (LFSM) failure | B14: M1 | C14: LFSM recovery outside | D14: Absent LFB issues:
C15: 70-130% for LFSM-High or | D15: Re-analysis of LFSM is required; Passing LFB confirms proper preparation and analysis so no further troubleshooting is necessary. If failure persists, samples analyzed since previous passing LFSM of same type (-Low/-High) must be flagged.
C16: 50-150% for LFSM-Low. Sample results may be biased proportionally due to matrix interferences.
D17: Coordinating LFSM/LFB failures:
C18: Note: Simultaneous failure of LFB and LFSM indicates systematic bias in the preparation or analysis processes. | D18: Re-preparation and re-analysis of LFB/LFSM required. Re-preparation of spiking solution (PDS/SDS) may also be necessary. If failure persists, samples analyzed since previous passing set of LFSM and LFB must be flagged.
A19: LFSM interference | B19: M2 | C19: Spike recovery unable to be calculated due to other factors, e.g. spiking concentration too low. | D19: Re-preparation and re-analysis of LFSM required. If failure persists, samples analyzed since previous passing LFSM of same type (-Low/-High) must be flagged. Analyst must describe in comments.
A20: Upper calibration limit exceeded | B20: UL | C20: Sample results are above the upper calibration limit. | D20: Sample must be re-analyzed at a higher dilution factor to obtain results within calibration range. Adjacent samples must be inspected for signs of carryover (see flag “C”).
A21: Lower calibration limit exceeded for diluted sample | B21: LL | C21: Sample dilution factor is greater than “2” but results are <MRL. Sample was therefore over-diluted. | D21: Sample must be re-analyzed at a lower dilution factor, undiluted if necessary, to obtain results within calibration range.
A22: Carryover/Contamination observed | B22: C | C22: Carryover and/or contamination observed in sample. Sample results are suspected to be biased high. | D22: Sample re-analysis is required.

Sheet Template
A1: Batch Name: | G1: SA: | H1: Area: | I1: SAH: | J1: AreaH: | K1: Last Acquisition Date: | N1: Sample Count: | P1: Analytes | Q1: PFBA | R1: L-PFBS | S1: HFPO-DA | T1: PFHxA | U1: L-PFHxS | V1: PFOA | W1: PFNA | X1: L-PFOS | Y1: PFDA | Z1: HCal Std | AB1: Sheet1_1 | AC1: =IFERROR(IF(COUNTIF($E$5:$E$999,"M")=0,"WARNING! NO CALIBRATION",IF(NOT(LARGE($A5:$A999,1)=VALUE($N$2)),"SAMPLE COUNT MISMATCH!",IF(NOT(LARGE($A5:$A999,1)=VALUE(VLOOKUP("Sample Count:",INDIRECT("'"&$AB$1&"'!"&"$A$1:$ZZ$999"),2,FALSE))),"SAMPLE COUNT MISMATCH!",IF(NOT(LARGE($A5:$A999,1)=VALUE(VLOOKUP("Sample Count:",INDIRECT("'"&$AB$2&"'!"&"$A$1:$ZZ$999"),2,FALSE))),"SAMPLE COUNT MISMATCH!",IF(NOT(LARGE($A5:$A999,1)=VALUE(VLOOKUP("Sample Count:",INDIRECT("'"&$AB$3&"'!"&"$A$1:$ZZ$999"),2,FALSE))),"SAMPLE COUNT MISMATCH!",""))))),"") | AT1: Verifier Count | AU1: Validator Count | AV1: MPFBA | AW1: M3PFBS | AX1: MPHFPO-DA | AY1: M5PFHxA | AZ1: M3PFHxS | BA1: M8PFOA | BB1: M9PFNA | BC1: M8PFOS | BD1: M6PFDA | BF1: Type | BO1: D (LD) | BP1: K (LRB) | BQ1: M (Cal) | BR1: CCC/QCS | BS1: S (LFSM) | BT1: Z (LFB) | BU1: IBC | BV1: <MRL | BW1: <MRL OVRD
A2: =IFERROR(VLOOKUP("Batch Name:",INDIRECT("'"&$G$2&"'!"&"$A$1:$ZZ$999"),2,FALSE),"") -> 44944 | G2: Sheet2 | H2: Sheet4 | I2: =IFERROR(MATCH("Data File",INDIRECT("'"&$G$2&"'!"&"$A$1:$A$999"),0),"") -> 8 | J2: =IFERROR(MATCH("Data File",INDIRECT("'"&$H$2&"'!"&"$A$1:$A$999"),0),"") -> 8 | K2: =IFERROR(VLOOKUP("Last Acquisition Date:",INDIRECT("'"&$G$2&"'!"&"$A$1:$ZZ$999"),2,FALSE),"") -> 44957.303 | N2: =IFERROR(VLOOKUP("Sample Count:",INDIRECT("'"&$G$2&"'!"&"$A$1:$ZZ$999"),2,FALSE),"") -> 365 | P2: MRL> | Q2: 5 | R2: 5 | S2: 5 | T2: 5 | U2: 5 | V2: 5 | W2: 5 | X2: 5 | Y2: 5 | Z2: {=MAX(IF($E$5:$E$999="M",$Z$5:$Z$999))} -> 0 | AB2: Sheet3 | AT2: =COUNTA($AT$5:$AT$1000) -> 0 | AU2: =COUNTA($AU$5:$AU$1000) -> 0 | AV2: {=IFERROR(MEDIAN(IF($E5:$E999="M",AV5:AV999)),"")} -> 365082.5 | AW2: {=IFERROR(MEDIAN(IF($E5:$E999="M",AW5:AW999)),"")} -> 740479.5 | AX2: {=IFERROR(MEDIAN(IF($E5:$E999="M",AX5:AX999)),"")} -> 1224004.5 | AY2: {=IFERROR(MEDIAN(IF($E5:$E999="M",AY5:AY999)),"")} -> 6800994.5 | AZ2: {=IFERROR(MEDIAN(IF($E5:$E999="M",AZ5:AZ999)),"")} -> 3376990.5 | BA2: {=IFERROR(MEDIAN(IF($E5:$E999="M",BA5:BA999)),"")} -> 27604846 | BB2: {=IFERROR(MEDIAN(IF($E5:$E999="M",BB5:BB999)),"")} -> 31889868 | BC2: {=IFERROR(MEDIAN(IF($E5:$E999="M",BC5:BC999)),"")} -> 3960175.5 | BD2: {=IFERROR(MEDIAN(IF($E5:$E999="M",BD5:BD999)),"")} -> 32794787 | BF2: U | BL2: Quality Control Maximum Recovery %: | BO2: 0.3 | BP2: 0.5 | BQ2: 0.3 | BR2: 0.3 | BS2: 0.3 | BT2: 0.3 | BU2: 0.2 | BV2: 0.5 | BW2: ON
G3: Measured Concentration, ng/L | Q3: Concentration, ng/L, Corrected for Sample Dilution | AB3: Sheet4 | AF3: Flags | AO3: Re-Analysis Flag | AS3: Verifier/Validator Initials | AV3: Area (Internal Standard) | BO3: Measured Concentration, ng/L | BY3: Quality Control Checks | CR3: These fields are editable with password: 'fixit'
A4: # | B4: Time Stamp: | C4: Sample ID: | D4: # | E4: Type | F4: QC? | G4: PFBA | H4: PFBS | I4: HFPO-DA | J4: PFHxA | K4: PFHxS | L4: PFOA | M4: PFNA | N4: PFOS | O4: PFDA | P4: Dilution Factor: | Q4: C-PFBA | R4: C-PFBS | S4: C-HFPO-DA | T4: C-PFHxA | U4: C-PFHxS | V4: C-PFOA | W4: C-PFNA | X4: C-PFOS | Y4: C-PFDA | Z4: True Value | AA4: True Value 2 | AB4: True Value 3 | AC4: Sample Type | AD4: ="Flags ("&COUNTIF(AD5:AD999,"Check!")+COUNTIF(AD5:AD999,"UL!")+COUNTIF(AD5:AD999,"No TrueV!")+COUNTIF(AD5:AD999,"No Match!")+COUNTIF(AD5:AD999,"Invalid Time!")&")" -> Flags (38) | AF4: F-PFBA | AG4: F-PFBS | AH4: F-HFPO-DA | AI4: F-PFHxA | AJ4: F-PFHxS | AK4: F-PFOA | AL4: F-PFNA | AM4: F-PFOS | AN4: F-PFDA | AP4: List for drop down flags | AQ4: Re-Analysis Flags | AS4: Sample Comments | AT4: Verifier Comments | AU4: Validator Comments | AV4: MPFBA | AW4: MPFBS | AX4: MPHFPO-DA | AY4: MPFHxA | AZ4: MPFHxS | BA4: MPFOA | BB4: MPFNA | BC4: MPFOS | BD4: MPFDA | BE4: IS Comments | BF4: M&Q | BG4: K&Z | BH4: D | BI4: S | BK4: # | BL4: QC Samples | BM4: Type | BN4: Dilution Factor: | BO4: PFBA | BP4: PFBS | BQ4: HFPO-DA | BR4: PFHxA | BS4: PFHxS | BT4: PFOA | BU4: PFNA | BV4: PFOS | BW4: PFDA | BX4: True Value | BY4: PFBA | BZ4: PFBS | CA4: HFPO-DA | CB4: PFHxA | CC4: PFHxS | CD4: PFOA | CE4: PFNA | CF4: PFOS | CG4: PFDA | CH4: PFBA | CI4: PFBS | CJ4: GenX | CK4: PFHxA | CL4: PFHxS | CM4: PFOA | CN4: PFNA | CO4: PFOS | CP4: PFDA | CQ4: Pairing
